<?xml version="1.0" encoding="utf-8"?>
<!-- =================================================================================== -->
<!-- |    This document was autogenerated by xacro from robots/EvaUnity.xacro          | -->
<!-- |    EDITING THIS FILE BY HAND IS NOT RECOMMENDED                                 | -->
<!-- =================================================================================== -->
<robot name="Eva">
  <joint name="torso_IE" type="revolute">
    <axis xyz="0 0 1"/>
    <parent link="part_torso_Ab-Ad"/>
    <child link="part_torso_IE"/>
    <origin xyz="0 0 0.05851"/>
    <limit effort="1.0" lower="-3.14159265359" upper="3.14159265359" velocity="1.0"/>
  </joint>
  <joint name="torso_Ab-Ad" type="revolute">
    <axis xyz="1 0 0"/>
    <parent link="pelvis"/>
    <child link="part_torso_Ab-Ad"/>
    <origin xyz="0 0 0.0"/>
    <limit effort="1.0" lower="-0.785398163397" upper="0.785398163397" velocity="1.0"/>
  </joint>
  <link name="part_torso_Ab-Ad">
    <visual>
      <geometry>
        <mesh filename="package://eva/model/meshes/part_torso_Ab-Ad.DAE"/>
      </geometry>
      <origin rpy="-1.57079632679 0 0" xyz="0 0 0.037"/>
      <material name="gold">
        <color rgba="1 0.549 0 1"/>
      </material>
    </visual>
	  <collision>
		  <geometry>
			  <mesh filename="package://eva/model/meshes/part_torso_Ab-Ad.PREFAB"/>
		  </geometry>
		  <origin rpy="-1.57079632679 0 0" xyz="0 0 0.037"/>
		  
	  </collision>
    <inertial>
      <origin xyz="0.000 0 0.037"/>
      <mass value="0.451043"/>
      <inertia ixx="0.000395" ixy="-0" ixz="-0" iyy="0.000384" iyz="-0" izz="0.000337"/>
    </inertial>
  </link>
  <link name="part_torso_IE">
    <visual>
      <geometry>
        <mesh filename="package://eva/model/meshes/part_torso_IE.DAE"/>
      </geometry>
      <origin rpy="0 0 0" xyz="0 0 0"/>
      <material name="gold">
        <color rgba="1 0.549 0 1"/>
      </material>
    </visual>
	  <collision>
		  <geometry>
			  <mesh filename="package://eva/model/meshes/part_torso_IE.PREFAB"/>
		  </geometry>
		  <origin rpy="0 0 0" xyz="0 0 0"/>

	  </collision>
    <inertial>
      <origin xyz="0.000050 0 0.008097"/>
      <mass value="0.085195"/>
      <inertia ixx="0.000016" ixy="-0" ixz="-0" iyy="0.000017" iyz="-0" izz="0.000020"/>
    </inertial>
  </link>
  <link name="pelvis">
    <visual>
      <geometry>
        <mesh filename="package://eva/model/meshes/part_torso_fixed.DAE"/>
      </geometry>
      <origin rpy="-1.57079632679 0 0" xyz="0 0 0"/>
      <material name="gold">
        <color rgba="1 0.549 0 1"/>
      </material>
    </visual>
	  <collision>
		  <geometry>
			  <mesh filename="package://eva/model/meshes/part_torso_fixed.PREFAB"/>
		  </geometry>
		  <origin rpy="-1.57079632679 0 0" xyz="0 0 0"/>
		  
	  </collision>
    <inertial>
      <origin xyz="0.028567 0 -0.067891"/>
      <mass value="0.801754"/>
      <inertia ixx="0.001877" ixy="-0.000253" ixz="0.000264" iyy="0.001567" iyz="0" izz="0.000902"/>
    </inertial>
  </link>
  <joint name="r_leg_back_fixed_y" type="fixed">
    <parent link="pelvis"/>
    <child link="part_r_leg_back_fixed_y"/>
    <origin xyz="0.0405 0.0875 -0.07925"/>
  </joint>
  <joint name="r_leg_hpz_1" type="revolute">
    <axis xyz="0 0 1"/>
    <parent link="part_r_leg_back_fixed_y"/>
    <child link="part_r_leg_hpz_1"/>
    <origin xyz="-0.0375 0 0"/>
    <limit effort="1.0" lower="-0.785398163397" upper="0.785398163397" velocity="1.0"/>
  </joint>
  <!-- Weird 2.5 mm X offset added because mesh isn't horizontal for some reason-->
  <joint name="r_leg_hpz_2" type="revolute">
    <axis xyz="0 0 1"/>
    <parent link="part_r_leg_hpz_1"/>
    <child link="part_r_leg_hpz_2"/>
    <origin xyz=".0025 0.0855 0"/>
    <limit effort="1.0" lower="-0.785398163397" upper="0.785398163397" velocity="1.0"/>
  </joint>
  <joint name="r_leg_hpz_3" type="revolute">
    <axis xyz="0 0 1"/>
    <parent link="part_r_leg_hpz_2"/>
    <child link="part_r_leg_hpz_3"/>
    <origin xyz="-0.04419 0.04419 0"/>
    <limit effort="1.0" lower="-0.785398163397" upper="0.785398163397" velocity="1.0"/>
  </joint>
  <joint name="r_leg_hpy" type="revolute">
    <axis xyz="1 0 0"/>
    <parent link="part_r_leg_hpz_3"/>
    <child link="part_r_leg_hpy"/>
    <origin xyz="-0.05295 0 0"/>
    <limit effort="1.0" lower="-0.785398163397" upper="0.785398163397" velocity="1.0"/>
  </joint>
  <joint name="r_leg_hpx" type="revolute">
    <axis xyz="0 1 0"/>
    <parent link="part_r_leg_hpy"/>
    <child link="part_r_leg_hpx"/>
    <origin xyz="-0.05883 0.0399 0"/>
    <limit effort="1.0" lower="-0.785398163397" upper="0.785398163397" velocity="1.0"/>
  </joint>
  <link name="part_r_leg_back_fixed_y">
    <visual>
      <geometry>
        <mesh filename="package://eva/model/meshes/part_hip_widthR.DAE"/>
      </geometry>
      <origin rpy="0 0 0" xyz="-0.0375 0 0"/>
      <material name="gold">
        <color rgba="1 0.549 0 1"/>
      </material>
    </visual>
	  <collision>
		  <geometry>
			  <mesh filename="package://eva/model/meshes/part_hip_widthR.PREFAB"/>
		  </geometry>
		  <origin rpy="0 0 0" xyz="-0.0375 0 0"/>
		  
	  </collision>
    <inertial>
      <origin xyz="-0.028265 -0.000198 0.022804"/>
      <mass value="0.373142 "/>
      <inertia ixx="0.000235" ixy="0.000012" ixz="0.0" iyy="0.000341" iyz="0.0" izz="0.000253"/>
    </inertial>
  </link>
  <link name="part_r_leg_hpz_1">
    <visual>
      <geometry>
        <mesh filename="package://eva/model/meshes/part_hip_IER_1.DAE"/>
      </geometry>
      <!-- rotation about Z is 0 for right side (sideInt = 1) and PI for left (sideInt = -1) -->
      <origin rpy="0 1.57079632679 0.0" xyz="0 0 0"/>
      <material name="gold">
        <color rgba="1 0.549 0 1"/>
      </material>
    </visual>
	  <collision>
		  <geometry>
			  <mesh filename="package://eva/model/meshes/part_hip_IER_1.PREFAB"/>
		  </geometry>
		  <!-- rotation about Z is 0 for right side (sideInt = 1) and PI for left (sideInt = -1) -->
		  <origin rpy="0 1.57079632679 0.0" xyz="0 0 0"/>
		  
	  </collision>
    <inertial>
      <origin xyz="0 0.04275 0"/>
      <mass value="0.226350  "/>
      <inertia ixx="0.000338" ixy="-0.0" ixz="0" iyy="0.000417" iyz="0" izz="0.000701"/>
    </inertial>
  </link>
  <link name="part_r_leg_hpz_2">
    <visual>
      <geometry>
        <mesh filename="package://eva/model/meshes/part_hip_IER_2.DAE"/>
      </geometry>
      <!-- rotation about Z is 0 for right side (sideInt = 1) and PI for left (sideInt = -1) -->
      <origin rpy="0 0 0.0" xyz="0 0 0"/>
      <material name="gold">
        <color rgba="1 0.549 0 1"/>
      </material>
    </visual>
	  <collision>
		  <geometry>
			  <mesh filename="package://eva/model/meshes/part_hip_IER_2.PREFAB"/>
		  </geometry>
		  <!-- rotation about Z is 0 for right side (sideInt = 1) and PI for left (sideInt = -1) -->
		  <origin rpy="0 0 0.0" xyz="0 0 0"/>
		  
	  </collision>
    <inertial>
      <origin xyz="-0.019418 0.024486 0"/>
      <mass value="0.558791"/>
      <inertia ixx="0.000436" ixy="0.000200" ixz="0" iyy="0" iyz="0" izz="0.000548"/>
    </inertial>
  </link>
  <link name="part_r_leg_hpz_3">
    <visual>
      <geometry>
        <mesh filename="package://eva/model/meshes/part_hip_IER_3.DAE"/>
      </geometry>
      <origin rpy="1.57079632679 -1.57079632679 0" xyz="-0.04607 0 0"/>
      <material name="gold">
        <color rgba="1 0.549 0 1"/>
      </material>
    </visual>
	  <collision>
		  <geometry>
			  <mesh filename="package://eva/model/meshes/part_hip_IER_3.PREFAB"/>
		  </geometry>
		  <origin rpy="1.57079632679 -1.57079632679 0" xyz="-0.04607 0 0"/>
		 
	  </collision>
    <inertial>
      <origin xyz="-0.027811 0.002981 -0.000033"/>
      <mass value="0.278587"/>
      <inertia ixx="0.000147" ixy="0" ixz="0" iyy="0" iyz="0" izz="0.000425"/>
    </inertial>
  </link>
  <link name="part_r_leg_hpy">
    <visual>
      <geometry>
        <mesh filename="package://eva/model/meshes/part_hip_Ab-AdR.DAE"/>
      </geometry>
      <origin rpy="0 0 0" xyz="0 0 0"/>
      <material name="gold">
        <color rgba="1 0.549 0 1"/>
      </material>
    </visual>
	  <collision>
		  <geometry>
			  <mesh filename="package://eva/model/meshes/part_hip_Ab-AdR.PREFAB"/>
		  </geometry>
		  <origin rpy="0 0 0" xyz="0 0 0"/>
		 
	  </collision>
    <inertial>
      <origin xyz="-0.056138 0.005431 0.000106"/>
      <mass value="0.961801"/>
      <inertia ixx="0.000809" ixy="-0.000001" ixz="0.000002" iyy="0.001286" iyz="0.000001" izz="0.000968"/>
    </inertial>
  </link>
  <link name="part_r_leg_hpx">
    <visual>
      <geometry>
        <mesh filename="package://eva/model/meshes/part_hip_FER.DAE"/>
      </geometry>
      <origin rpy="0 0 0" xyz="0 0 0"/>
      <material name="gold">
        <color rgba="1 0.549 0 1"/>
      </material>
    </visual>
	  <collision>
		  <geometry>
			  <mesh filename="package://eva/model/meshes/part_hip_FER.PREFAB"/>
		  </geometry>
		  <origin rpy="0 0 0" xyz="0 0 0"/>
		 
	  </collision>
    <inertial>
      <origin xyz="-0.004526 -0.020872 -0.161098"/>
      <mass value="1.028683"/>
      <inertia ixx="0.012939" ixy="0.000005" ixz="-0.000078" iyy="0.013361" iyz="-0.001448" izz="0.001388"/>
    </inertial>
  </link>
  <joint name="l_leg_back_fixed_y" type="fixed">
    <parent link="pelvis"/>
    <child link="part_l_leg_back_fixed_y"/>
    <origin xyz="0.0405 -0.0875 -0.07925"/>
  </joint>
  <joint name="l_leg_hpz_1" type="revolute">
    <axis xyz="0 0 1"/>
    <parent link="part_l_leg_back_fixed_y"/>
    <child link="part_l_leg_hpz_1"/>
    <origin xyz="-0.0375 0 0"/>
    <limit effort="1.0" lower="-0.785398163397" upper="0.785398163397" velocity="1.0"/>
  </joint>
  <!-- Weird 2.5 mm X offset added because mesh isn't horizontal for some reason-->
  <joint name="l_leg_hpz_2" type="revolute">
    <axis xyz="0 0 1"/>
    <parent link="part_l_leg_hpz_1"/>
    <child link="part_l_leg_hpz_2"/>
    <origin xyz=".0025 -0.0855 0"/>
    <limit effort="1.0" lower="-0.785398163397" upper="0.785398163397" velocity="1.0"/>
  </joint>
  <joint name="l_leg_hpz_3" type="revolute">
    <axis xyz="0 0 1"/>
    <parent link="part_l_leg_hpz_2"/>
    <child link="part_l_leg_hpz_3"/>
    <origin xyz="-0.04419 -0.04419 0"/>
    <limit effort="1.0" lower="-0.785398163397" upper="0.785398163397" velocity="1.0"/>
  </joint>
  <joint name="l_leg_hpy" type="revolute">
    <axis xyz="1 0 0"/>
    <parent link="part_l_leg_hpz_3"/>
    <child link="part_l_leg_hpy"/>
    <origin xyz="-0.05295 0 0"/>
    <limit effort="1.0" lower="-0.785398163397" upper="0.785398163397" velocity="1.0"/>
  </joint>
  <joint name="l_leg_hpx" type="revolute">
    <axis xyz="0 1 0"/>
    <parent link="part_l_leg_hpy"/>
    <child link="part_l_leg_hpx"/>
    <origin xyz="-0.05883 -0.0399 0"/>
    <limit effort="1.0" lower="-0.785398163397" upper="0.785398163397" velocity="1.0"/>
  </joint>
  <link name="part_l_leg_back_fixed_y">
    <visual>
      <geometry>
        <mesh filename="package://eva/model/meshes/part_hip_widthL.DAE"/>
      </geometry>
      <origin rpy="0 0 0" xyz="-0.0375 0 0"/>
      <material name="gold">
        <color rgba="1 0.549 0 1"/>
      </material>
    </visual>
	  <collision>
		  <geometry>
			  <mesh filename="package://eva/model/meshes/part_hip_widthL.PREFAB"/>
		  </geometry>
		  <origin rpy="0 0 0" xyz="-0.0375 0 0"/>
		  
	  </collision>
    <inertial>
      <origin xyz="-0.028265 0.000198 0.022804"/>
      <mass value="0.373142 "/>
      <inertia ixx="0.000235" ixy="0.000012" ixz="0.0" iyy="0.000341" iyz="0.0" izz="0.000253"/>
    </inertial>
  </link>
  <link name="part_l_leg_hpz_1">
    <visual>
      <geometry>
        <mesh filename="package://eva/model/meshes/part_hip_IEL_1.DAE"/>
      </geometry>
      <!-- rotation about Z is 0 for right side (sideInt = 1) and PI for left (sideInt = -1) -->
      <origin rpy="0 -1.57079632679 3.14159265359" xyz="0 0 0"/>
      <material name="gold">
        <color rgba="1 0.549 0 1"/>
      </material>
    </visual>
	  <collision>
		  <geometry>
			  <mesh filename="package://eva/model/meshes/part_hip_IEL_1.PREFAB"/>
		  </geometry>
		  <!-- rotation about Z is 0 for right side (sideInt = 1) and PI for left (sideInt = -1) -->
		  <origin rpy="0 -1.57079632679 3.14159265359" xyz="0 0 0"/>
		  
	  </collision>
    <inertial>
      <origin xyz="0 -0.04275 0"/>
      <mass value="0.226350  "/>
      <inertia ixx="0.000338" ixy="-0.0" ixz="0" iyy="0.000417" iyz="0" izz="0.000701"/>
    </inertial>
  </link>
  <link name="part_l_leg_hpz_2">
    <visual>
      <geometry>
        <mesh filename="package://eva/model/meshes/part_hip_IEL_2.DAE"/>
      </geometry>
      <!-- rotation about Z is 0 for right side (sideInt = 1) and PI for left (sideInt = -1) -->
      <origin rpy="0 0 3.14159265359" xyz="0 0 0"/>
      <material name="gold">
        <color rgba="1 0.549 0 1"/>
      </material>
    </visual>
	  <collision>
		  <geometry>
			  <mesh filename="package://eva/model/meshes/part_hip_IEL_2.PREFAB"/>
		  </geometry>
		  <!-- rotation about Z is 0 for right side (sideInt = 1) and PI for left (sideInt = -1) -->
		  <origin rpy="0 0 3.14159265359" xyz="0 0 0"/>
		  
	  </collision>
    <inertial>
      <origin xyz="-0.019418 -0.024486 0"/>
      <mass value="0.558791"/>
      <inertia ixx="0.000436" ixy="0.000200" ixz="0" iyy="0" iyz="0" izz="0.000548"/>
    </inertial>
  </link>
  <link name="part_l_leg_hpz_3">
    <visual>
      <geometry>
        <mesh filename="package://eva/model/meshes/part_hip_IEL_3.DAE"/>
      </geometry>
      <origin rpy="1.57079632679 1.57079632679 0" xyz="-0.04607 0 0"/>
      <material name="gold">
        <color rgba="1 0.549 0 1"/>
      </material>
    </visual>
	  <collision>
		  <geometry>
			  <mesh filename="package://eva/model/meshes/part_hip_IEL_3.PREFAB"/>
		  </geometry>
		  <origin rpy="1.57079632679 1.57079632679 0" xyz="-0.04607 0 0"/>
		  
	  </collision>
    <inertial>
      <origin xyz="-0.027811 -0.002981 -0.000033"/>
      <mass value="0.278587"/>
      <inertia ixx="0.000147" ixy="0" ixz="0" iyy="0" iyz="0" izz="0.000425"/>
    </inertial>
  </link>
  <link name="part_l_leg_hpy">
    <visual>
      <geometry>
        <mesh filename="package://eva/model/meshes/part_hip_Ab-AdL.DAE"/>
      </geometry>
      <origin rpy="0 0 0" xyz="0 0 0"/>
      <material name="gold">
        <color rgba="1 0.549 0 1"/>
      </material>
    </visual>
	  <collision>
		  <geometry>
			  <mesh filename="package://eva/model/meshes/part_hip_Ab-AdL.PREFAB"/>
		  </geometry>
		  <origin rpy="0 0 0" xyz="0 0 0"/>
		  
	  </collision>
    <inertial>
      <origin xyz="-0.056138 -0.005431 0.000106"/>
      <mass value="0.961801"/>
      <inertia ixx="0.000809" ixy="-0.000001" ixz="0.000002" iyy="0.001286" iyz="0.000001" izz="0.000968"/>
    </inertial>
  </link>
  <link name="part_l_leg_hpx">
    <visual>
      <geometry>
        <mesh filename="package://eva/model/meshes/part_hip_FEL.DAE"/>
      </geometry>
      <origin rpy="0 0 0" xyz="0 0 0"/>
      <material name="gold">
        <color rgba="1 0.549 0 1"/>
      </material>
    </visual>
	  <collision>
		  <geometry>
			  <mesh filename="package://eva/model/meshes/part_hip_FEL.PREFAB"/>
		  </geometry>
		  <origin rpy="0 0 0" xyz="0 0 0"/>
		 
	  </collision>
    <inertial>
      <origin xyz="-0.004526 0.020872 -0.161098"/>
      <mass value="1.028683"/>
      <inertia ixx="0.012939" ixy="0.000005" ixz="-0.000078" iyy="0.013361" iyz="-0.001448" izz="0.001388"/>
    </inertial>
  </link>
  <joint name="r_leg_kn_pulley_y" type="revolute">
    <axis xyz="0 1 0"/>
    <parent link="part_r_leg_hpx"/>
    <child link="part_r_leg_kn_pulley_y"/>
    <origin xyz="-0.00248 -0.0231 -0.32192"/>
    <limit effort="1.0" lower="-1.57079632679" upper="0.196349540849" velocity="1.0"/>
  </joint>
  <!--This joint mirrors the joint above it because it's a gear-->
  <joint name="r_leg_kn_follower_y" type="revolute">
    <axis xyz="0 1 0"/>
    <parent link="part_r_leg_kn_pulley_y"/>
    <child link="part_r_leg_kn_follower_y"/>
    <mimic joint="r_leg_kn_pulley_y" mulitplier="-1"/>
    <origin xyz="-0.00046 0.00431 -0.064"/>
    <limit effort="1.0" lower="-1.57079632679" upper="0.196349540849" velocity="1.0"/>
  </joint>
  <joint name="r_leg_kn_z" type="revolute">
    <axis xyz="0 0 1"/>
    <parent link="part_r_leg_kn_follower_y"/>
    <child link="part_r_leg_kn_z"/>
    <origin xyz="-0.0001 -0.00091 -0.0755"/>
    <limit effort="1.0" lower="-2.74889357189" upper="2.74889357189" velocity="1.0"/>
  </joint>
  <link name="part_r_leg_kn_pulley_y">
    <visual>
      <geometry>
        <mesh filename="package://eva/model/meshes/part_knee_FER_1.DAE"/>
      </geometry>
      <origin rpy="0 0 0" xyz="0 0 0"/>
      <material name="gold">
        <color rgba="1 0.549 0 1"/>
      </material>
    </visual>
	  <collision>
		  <geometry>
			  <mesh filename="package://eva/model/meshes/part_knee_FER_1.PREFAB"/>
		  </geometry>
		  <origin rpy="0 0 0" xyz="0 0 0"/>
		 
	  </collision>
    <inertial>
      <origin xyz="0.001012 0.009407 0.043646"/>
      <mass value="0.251805 "/>
      <inertia ixx="0.000296" ixy="-0.000003" ixz="-0.000005" iyy="0.000266" iyz="-0.000047" izz="0.000126"/>
    </inertial>
  </link>
  <link name="part_r_leg_kn_follower_y">
    <visual>
      <geometry>
        <mesh filename="package://eva/model/meshes/part_knee_FER_2.DAE"/>
      </geometry>
      <origin rpy="0 0 0" xyz="0 0 0"/>
      <material name="gold">
        <color rgba="1 0.549 0 1"/>
      </material>
    </visual>
	  <collision>
		  <geometry>
			  <mesh filename="package://eva/model/meshes/part_knee_FER_2.PREFAB"/>
		  </geometry>
		  <origin rpy="0 0 0" xyz="0 0 0"/>
		  
	  </collision>
    <inertial>
      <origin xyz="-0.001156 -0.001236 -0.016280"/>
      <mass value="0.209036"/>
      <inertia ixx="0.000233" ixy="0" ixz="0.000012" iyy="0.000011" iyz="0.000011" izz="0.000065"/>
    </inertial>
  </link>
  <link name="part_r_leg_kn_z">
    <visual>
      <geometry>
        <mesh filename="package://eva/model/meshes/part_knee_IER.DAE"/>
      </geometry>
      <origin rpy="0 0 0" xyz="0 0 0"/>
      <material name="gold">
        <color rgba="1 0.549 0 1"/>
      </material>
    </visual>
	  <collision>
		  <geometry>
			  <mesh filename="package://eva/model/meshes/part_knee_IER.PREFAB"/>
		  </geometry>
		  <origin rpy="0 0 0" xyz="0 0 0"/>
		 
	  </collision>
    <inertial>
      <origin xyz="-0.002177 -0.023571 -0.234763"/>
      <mass value="0.800411"/>
      <inertia ixx="0.009841" ixy="-0.000012" ixz="-0.000012" iyy="0.008790" iyz="-0.001295" izz="0.001181"/>
    </inertial>
  </link>
  <joint name="l_leg_kn_pulley_y" type="revolute">
    <axis xyz="0 1 0"/>
    <parent link="part_l_leg_hpx"/>
    <child link="part_l_leg_kn_pulley_y"/>
    <origin xyz="-0.00248 0.0231 -0.32192"/>
    <limit effort="1.0" lower="-1.57079632679" upper="0.196349540849" velocity="1.0"/>
  </joint>
  <!--This joint mirrors the joint above it because it's a gear-->
  <joint name="l_leg_kn_follower_y" type="revolute">
    <axis xyz="0 1 0"/>
    <parent link="part_l_leg_kn_pulley_y"/>
    <child link="part_l_leg_kn_follower_y"/>
    <mimic joint="l_leg_kn_pulley_y" mulitplier="-1"/>
    <origin xyz="-0.00046 -0.00431 -0.064"/>
    <limit effort="1.0" lower="-1.57079632679" upper="0.196349540849" velocity="1.0"/>
  </joint>
  <joint name="l_leg_kn_z" type="revolute">
    <axis xyz="0 0 1"/>
    <parent link="part_l_leg_kn_follower_y"/>
    <child link="part_l_leg_kn_z"/>
    <origin xyz="-0.0001 0.00091 -0.0755"/>
    <limit effort="1.0" lower="-2.74889357189" upper="2.74889357189" velocity="1.0"/>
  </joint>
  <link name="part_l_leg_kn_pulley_y">
    <visual>
      <geometry>
        <mesh filename="package://eva/model/meshes/part_knee_FEL_1.DAE"/>
      </geometry>
      <origin rpy="0 0 0" xyz="0 0 0"/>
      <material name="gold">
        <color rgba="1 0.549 0 1"/>
      </material>
    </visual>
	  <collision>
		  <geometry>
			  <mesh filename="package://eva/model/meshes/part_knee_FEL_1.PREFAB"/>
		  </geometry>
		  <origin rpy="0 0 0" xyz="0 0 0"/>
		 
	  </collision>
    <inertial>
      <origin xyz="0.001012 -0.009407 0.043646"/>
      <mass value="0.251805 "/>
      <inertia ixx="0.000296" ixy="-0.000003" ixz="-0.000005" iyy="0.000266" iyz="-0.000047" izz="0.000126"/>
    </inertial>
  </link>
  <link name="part_l_leg_kn_follower_y">
    <visual>
      <geometry>
        <mesh filename="package://eva/model/meshes/part_knee_FEL_2.DAE"/>
      </geometry>
      <origin rpy="0 0 0" xyz="0 0 0"/>
      <material name="gold">
        <color rgba="1 0.549 0 1"/>
      </material>
    </visual>
	  <collision>
		  <geometry>
			  <mesh filename="package://eva/model/meshes/part_knee_FEL_2.PREFAB"/>
		  </geometry>
		  <origin rpy="0 0 0" xyz="0 0 0"/>
		  
	  </collision>
    <inertial>
      <origin xyz="-0.001156 0.001236 -0.016280"/>
      <mass value="0.209036"/>
      <inertia ixx="0.000233" ixy="0" ixz="0.000012" iyy="0.000011" iyz="0.000011" izz="0.000065"/>
    </inertial>
  </link>
  <link name="part_l_leg_kn_z">
    <visual>
      <geometry>
        <mesh filename="package://eva/model/meshes/part_knee_IEL.DAE"/>
      </geometry>
      <origin rpy="0 0 0" xyz="0 0 0"/>
      <material name="gold">
        <color rgba="1 0.549 0 1"/>
      </material>
    </visual>
	  <collision>
		  <geometry>
			  <mesh filename="package://eva/model/meshes/part_knee_IEL.PREFAB"/>
		  </geometry>
		  <origin rpy="0 0 0" xyz="0 0 0"/>
		 
	  </collision>
    <inertial>
      <origin xyz="-0.002177 0.023571 -0.234763"/>
      <mass value="0.800411"/>
      <inertia ixx="0.009841" ixy="-0.000012" ixz="-0.000012" iyy="0.008790" iyz="-0.001295" izz="0.001181"/>
    </inertial>
  </link>
</robot>

